Workbook

Sheet Data (Empaneled)
A1: AMALAPURAM | B1: State | C1: City (as entered) | D1: City (cleaned) | E1: Tier | F1: Cardiology | G1: Oncology | H1: Ophthalmology | I1: Maternal Health (OBGY) | J1: Neonatology | K1: Key: State|Tier | L1: Key: State|City | M1: Key Cardiology | N1: Key Oncology | O1: Key Ophthalmology | P1: Key Maternal Health (OBGY) | Q1: Key Neonatology
A2: PANACEA NURSING HOME | B2: West Bengal | C2: 24 PGS (N) | D2: Pgs N | E2: Tier 3 | F2: Yes | G2: Yes | H2: No | I2: Yes | J2: Yes | K2: =$B2&"|"&$E2 -> West Bengal|Tier 3 | L2: =$B2&"|"&$D2 -> West Bengal|Pgs N | M2: =IF($F2="Yes",$L2,"") -> West Bengal|Pgs N | N2: =IF($G2="Yes",$L2,"") -> West Bengal|Pgs N | O2: =IF($H2="Yes",$L2,"") | P2: =IF($I2="Yes",$L2,"") -> West Bengal|Pgs N | Q2: =IF($J2="Yes",$L2,"") -> West Bengal|Pgs N
A3: THE SAHARARHAT JIS HOSPITAL | B3: West Bengal | C3: 24 PGS (S) | D3: Pgs S | E3: Tier 3 | F3: Yes | G3: Yes | H3: No | I3: Yes | J3: Yes | K3: =$B3&"|"&$E3 -> West Bengal|Tier 3 | L3: =$B3&"|"&$D3 -> West Bengal|Pgs S | M3: =IF($F3="Yes",$L3,"") -> West Bengal|Pgs S | N3: =IF($G3="Yes",$L3,"") -> West Bengal|Pgs S | O3: =IF($H3="Yes",$L3,"") | P3: =IF($I3="Yes",$L3,"") -> West Bengal|Pgs S | Q3: =IF($J3="Yes",$L3,"") -> West Bengal|Pgs S
A4: Pooja Critical Care Neuro and Trauma Hospital | B4: Madhya Pradesh | C4: 485001 | D4: Satna | E4: Tier 3 | F4: No | G4: No | H4: Yes | I4: Yes | J4: Yes | K4: =$B4&"|"&$E4 -> Madhya Pradesh|Tier 3 | L4: =$B4&"|"&$D4 -> Madhya Pradesh|Satna | M4: =IF($F4="Yes",$L4,"") | N4: =IF($G4="Yes",$L4,"") | O4: =IF($H4="Yes",$L4,"") -> Madhya Pradesh|Satna | P4: =IF($I4="Yes",$L4,"") -> Madhya Pradesh|Satna | Q4: =IF($J4="Yes",$L4,"") -> Madhya Pradesh|Satna
A5: THE LIFE CARE | B5: West Bengal | C5: 721636 | D5: Tamluk | E5: Tier 3 | F5: No | G5: Yes | H5: No | I5: Yes | J5: Yes | K5: =$B5&"|"&$E5 -> West Bengal|Tier 3 | L5: =$B5&"|"&$D5 -> West Bengal|Tamluk | M5: =IF($F5="Yes",$L5,"") | N5: =IF($G5="Yes",$L5,"") -> West Bengal|Tamluk | O5: =IF($H5="Yes",$L5,"") | P5: =IF($I5="Yes",$L5,"") -> West Bengal|Tamluk | Q5: =IF($J5="Yes",$L5,"") -> West Bengal|Tamluk
A6: SUDHA MULTISPECIALTY HOSPITAL AND HIGH-RISK PREGNANCY CENTRE | B6: Madhya Pradesh | C6: 837 GOL BAZARJABALPUR MADHYAPRADESH 482002 | D6: Jabalpur | E6: Tier 2B | F6: No | G6: No | H6: Yes | I6: Yes | J6: No | K6: =$B6&"|"&$E6 -> Madhya Pradesh|Tier 2B | L6: =$B6&"|"&$D6 -> Madhya Pradesh|Jabalpur | M6: =IF($F6="Yes",$L6,"") | N6: =IF($G6="Yes",$L6,"") | O6: =IF($H6="Yes",$L6,"") -> Madhya Pradesh|Jabalpur | P6: =IF($I6="Yes",$L6,"") -> Madhya Pradesh|Jabalpur | Q6: =IF($J6="Yes",$L6,"")
A7: ANGEL HOSPITAL (A unit of SehatMitra Healthtech Private Limited) | B7: Punjab | C7: ABOHAR | D7: Abohar | E7: Tier 3 | F7: No | G7: Yes | H7: Yes | I7: Yes | J7: Yes | K7: =$B7&"|"&$E7 -> Punjab|Tier 3 | L7: =$B7&"|"&$D7 -> Punjab|Abohar | M7: =IF($F7="Yes",$L7,"") | N7: =IF($G7="Yes",$L7,"") -> Punjab|Abohar | O7: =IF($H7="Yes",$L7,"") -> Punjab|Abohar | P7: =IF($I7="Yes",$L7,"") -> Punjab|Abohar | Q7: =IF($J7="Yes",$L7,"") -> Punjab|Abohar
A8: SATYAVATHI EYE HOSPITAL | B8: Telangana | C8: ADDANKI | D8: Addanki | E8: Tier 3 | F8: No | G8: No | H8: No | I8: No | J8: No | K8: =$B8&"|"&$E8 -> Telangana|Tier 3 | L8: =$B8&"|"&$D8 -> Telangana|Addanki | M8: =IF($F8="Yes",$L8,"") | N8: =IF($G8="Yes",$L8,"") | O8: =IF($H8="Yes",$L8,"") | P8: =IF($I8="Yes",$L8,"") | Q8: =IF($J8="Yes",$L8,"")
A9: ARK HOSPITALS | B9: Telangana | C9: adilabad | D9: Adilabad | E9: Tier 3 | F9: No | G9: No | H9: No | I9: Yes | J9: No | K9: =$B9&"|"&$E9 -> Telangana|Tier 3 | L9: =$B9&"|"&$D9 -> Telangana|Adilabad | M9: =IF($F9="Yes",$L9,"") | N9: =IF($G9="Yes",$L9,"") | O9: =IF($H9="Yes",$L9,"") | P9: =IF($I9="Yes",$L9,"") -> Telangana|Adilabad | Q9: =IF($J9="Yes",$L9,"")
A10: KARTIKEYA HOSPITAL | B10: Telangana | C10: ADILABAD | D10: Adilabad | E10: Tier 3 | F10: No | G10: No | H10: No | I10: Yes | J10: No | K10: =$B10&"|"&$E10 -> Telangana|Tier 3 | L10: =$B10&"|"&$D10 -> Telangana|Adilabad | M10: =IF($F10="Yes",$L10,"") | N10: =IF($G10="Yes",$L10,"") | O10: =IF($H10="Yes",$L10,"") | P10: =IF($I10="Yes",$L10,"") -> Telangana|Adilabad | Q10: =IF($J10="Yes",$L10,"")
A11: SURAKSHA CHILDRENS HOSPITAL | B11: Telangana | C11: ADILABAD | D11: Adilabad | E11: Tier 3 | F11: No | G11: No | H11: No | I11: No | J11: Yes | K11: =$B11&"|"&$E11 -> Telangana|Tier 3 | L11: =$B11&"|"&$D11 -> Telangana|Adilabad | M11: =IF($F11="Yes",$L11,"") | N11: =IF($G11="Yes",$L11,"") | O11: =IF($H11="Yes",$L11,"") | P11: =IF($I11="Yes",$L11,"") | Q11: =IF($J11="Yes",$L11,"") -> Telangana|Adilabad
A12: ADITYA NURSING HOME | B12: Andhra Pradesh | C12: ADONI | D12: Adoni | E12: Tier 3 | F12: No | G12: No | H12: No | I12: Yes | J12: Yes | K12: =$B12&"|"&$E12 -> Andhra Pradesh|Tier 3 | L12: =$B12&"|"&$D12 -> Andhra Pradesh|Adoni | M12: =IF($F12="Yes",$L12,"") | N12: =IF($G12="Yes",$L12,"") | O12: =IF($H12="Yes",$L12,"") | P12: =IF($I12="Yes",$L12,"") -> Andhra Pradesh|Adoni | Q12: =IF($J12="Yes",$L12,"") -> Andhra Pradesh|Adoni
A13: MOUNT ZION MEDICAL COLLEGE HOSPITAL | B13: Kerala | C13: ADOOR | D13: Adoor | E13: Tier 3 | F13: Yes | G13: Yes | H13: Yes | I13: Yes | J13: No | K13: =$B13&"|"&$E13 -> Kerala|Tier 3 | L13: =$B13&"|"&$D13 -> Kerala|Adoor | M13: =IF($F13="Yes",$L13,"") -> Kerala|Adoor | N13: =IF($G13="Yes",$L13,"") -> Kerala|Adoor | O13: =IF($H13="Yes",$L13,"") -> Kerala|Adoor | P13: =IF($I13="Yes",$L13,"") -> Kerala|Adoor | Q13: =IF($J13="Yes",$L13,"")
... A3532: lions club of jamalpur welfare trust | B3532: Punjab | C3532: Zirakpur, Punjab | D3532: Zirakpur | E3532: Tier 3 | F3532: No | G3532: No | H3532: No | I3532: No | J3532: No | K3532: =$B3532&"|"&$E3532 -> Punjab|Tier 3 | L3532: =$B3532&"|"&$D3532 -> Punjab|Zirakpur | M3532: =IF($F3532="Yes",$L3532,"") | N3532: =IF($G3532="Yes",$L3532,"") | O3532: =IF($H3532="Yes",$L3532,"") | P3532: =IF($I3532="Yes",$L3532,"") | Q3532: =IF($J3532="Yes",$L3532,"")

Sheet Report

Sheet Sheet1

Sheet State-wise Summary
A1: State-wise Empaneled Hospital Distribution by City Tier
A2: Data: CEP master export, 3,530 hospitals at Status = 'Empaneled' as of 11 Aug 2026 (of 14,016 total registrations). City tier per GIC's Tier 1/2A/2B/3 city categorization.
A4: State | B4: Total Empaneled | C4: Tier 1 | D4: Tier 2A | E4: Tier 2B | F4: Tier 3 | G4: Cardiology % | H4: Oncology % | I4: Ophthalmology % | J4: Maternal Health (OBGY) % | K4: Neonatology % | M4: Check: tiers = total
A5: Andhra Pradesh | B5: =COUNTIF('Data (Empaneled)'!$B$2:$B$3532,$A5) -> 172 | C5: =COUNTIF('Data (Empaneled)'!$K$2:$K$3532,$N5) -> 0 | D5: =COUNTIF('Data (Empaneled)'!$K$2:$K$3532,$O5) -> 15 | E5: =COUNTIF('Data (Empaneled)'!$K$2:$K$3532,$P5) -> 23 | F5: =COUNTIF('Data (Empaneled)'!$K$2:$K$3532,$Q5) -> 134 | G5: =IFERROR(COUNTIFS('Data (Empaneled)'!$B$2:$B$3532,$A5,'Data (Empaneled)'!$F$2:$F$3532,"Yes")/$B5,0) -> 0.26162791 | H5: =IFERROR(COUNTIFS('Data (Empaneled)'!$B$2:$B$3532,$A5,'Data (Empaneled)'!$G$2:$G$3532,"Yes")/$B5,0) -> 0.12790698 | I5: =IFERROR(COUNTIFS('Data (Empaneled)'!$B$2:$B$3532,$A5,'Data (Empaneled)'!$H$2:$H$3532,"Yes")/$B5,0) -> 0.28488372 | J5: =IFERROR(COUNTIFS('Data (Empaneled)'!$B$2:$B$3532,$A5,'Data (Empaneled)'!$I$2:$I$3532,"Yes")/$B5,0) -> 0.73255814 | K5: =IFERROR(COUNTIFS('Data (Empaneled)'!$B$2:$B$3532,$A5,'Data (Empaneled)'!$J$2:$J$3532,"Yes")/$B5,0) -> 0.34883721 | M5: =IF(SUM(C5:F5)=B5,"OK","MISMATCH") -> OK | N5: =$A5&"|Tier 1" -> Andhra Pradesh|Tier 1 | O5: =$A5&"|Tier 2A" -> Andhra Pradesh|Tier 2A | P5: =$A5&"|Tier 2B" -> Andhra Pradesh|Tier 2B | Q5: =$A5&"|Tier 3" -> Andhra Pradesh|Tier 3
A6: Assam | B6: =COUNTIF('Data (Empaneled)'!$B$2:$B$3532,$A6) -> 10 | C6: =COUNTIF('Data (Empaneled)'!$K$2:$K$3532,$N6) -> 0 | D6: =COUNTIF('Data (Empaneled)'!$K$2:$K$3532,$O6) -> 0 | E6: =COUNTIF('Data (Empaneled)'!$K$2:$K$3532,$P6) -> 2 | F6: =COUNTIF('Data (Empaneled)'!$K$2:$K$3532,$Q6) -> 8 | G6: =IFERROR(COUNTIFS('Data (Empaneled)'!$B$2:$B$3532,$A6,'Data (Empaneled)'!$F$2:$F$3532,"Yes")/$B6,0) -> 0.4 | H6: =IFERROR(COUNTIFS('Data (Empaneled)'!$B$2:$B$3532,$A6,'Data (Empaneled)'!$G$2:$G$3532,"Yes")/$B6,0) -> 0.4 | I6: =IFERROR(COUNTIFS('Data (Empaneled)'!$B$2:$B$3532,$A6,'Data (Empaneled)'!$H$2:$H$3532,"Yes")/$B6,0) -> 0.6 | J6: =IFERROR(COUNTIFS('Data (Empaneled)'!$B$2:$B$3532,$A6,'Data (Empaneled)'!$I$2:$I$3532,"Yes")/$B6,0) -> 0.7 | K6: =IFERROR(COUNTIFS('Data (Empaneled)'!$B$2:$B$3532,$A6,'Data (Empaneled)'!$J$2:$J$3532,"Yes")/$B6,0) -> 0.7 | M6: =IF(SUM(C6:F6)=B6,"OK","MISMATCH") -> OK | N6: =$A6&"|Tier 1" -> Assam|Tier 1 | O6: =$A6&"|Tier 2A" -> Assam|Tier 2A | P6: =$A6&"|Tier 2B" -> Assam|Tier 2B | Q6: =$A6&"|Tier 3" -> Assam|Tier 3
A7: Bihar | B7: =COUNTIF('Data (Empaneled)'!$B$2:$B$3532,$A7) -> 111 | C7: =COUNTIF('Data (Empaneled)'!$K$2:$K$3532,$N7) -> 0 | D7: =COUNTIF('Data (Empaneled)'!$K$2:$K$3532,$O7) -> 55 | E7: =COUNTIF('Data (Empaneled)'!$K$2:$K$3532,$P7) -> 0 | F7: =COUNTIF('Data (Empaneled)'!$K$2:$K$3532,$Q7) -> 56 | G7: =IFERROR(COUNTIFS('Data (Empaneled)'!$B$2:$B$3532,$A7,'Data (Empaneled)'!$F$2:$F$3532,"Yes")/$B7,0) -> 0.46846847 | H7: =IFERROR(COUNTIFS('Data (Empaneled)'!$B$2:$B$3532,$A7,'Data (Empaneled)'!$G$2:$G$3532,"Yes")/$B7,0) -> 0.28828829 | I7: =IFERROR(COUNTIFS('Data (Empaneled)'!$B$2:$B$3532,$A7,'Data (Empaneled)'!$H$2:$H$3532,"Yes")/$B7,0) -> 0.38738739 | J7: =IFERROR(COUNTIFS('Data (Empaneled)'!$B$2:$B$3532,$A7,'Data (Empaneled)'!$I$2:$I$3532,"Yes")/$B7,0) -> 0.68468468 | K7: =IFERROR(COUNTIFS('Data (Empaneled)'!$B$2:$B$3532,$A7,'Data (Empaneled)'!$J$2:$J$3532,"Yes")/$B7,0) -> 0.45945946 | M7: =IF(SUM(C7:F7)=B7,"OK","MISMATCH") -> OK | N7: =$A7&"|Tier 1" -> Bihar|Tier 1 | O7: =$A7&"|Tier 2A" -> Bihar|Tier 2A | P7: =$A7&"|Tier 2B" -> Bihar|Tier 2B | Q7: =$A7&"|Tier 3" -> Bihar|Tier 3
A8: Chandigarh | B8: =COUNTIF('Data (Empaneled)'!$B$2:$B$3532,$A8) -> 3 | C8: =COUNTIF('Data (Empaneled)'!$K$2:$K$3532,$N8) -> 0 | D8: =COUNTIF('Data (Empaneled)'!$K$2:$K$3532,$O8) -> 3 | E8: =COUNTIF('Data (Empaneled)'!$K$2:$K$3532,$P8) -> 0 | F8: =COUNTIF('Data (Empaneled)'!$K$2:$K$3532,$Q8) -> 0 | G8: =IFERROR(COUNTIFS('Data (Empaneled)'!$B$2:$B$3532,$A8,'Data (Empaneled)'!$F$2:$F$3532,"Yes")/$B8,0) -> 0 | H8: =IFERROR(COUNTIFS('Data (Empaneled)'!$B$2:$B$3532,$A8,'Data (Empaneled)'!$G$2:$G$3532,"Yes")/$B8,0) -> 0.33333333 | I8: =IFERROR(COUNTIFS('Data (Empaneled)'!$B$2:$B$3532,$A8,'Data (Empaneled)'!$H$2:$H$3532,"Yes")/$B8,0) -> 0.66666667 | J8: =IFERROR(COUNTIFS('Data (Empaneled)'!$B$2:$B$3532,$A8,'Data (Empaneled)'!$I$2:$I$3532,"Yes")/$B8,0) -> 0.33333333 | K8: =IFERROR(COUNTIFS('Data (Empaneled)'!$B$2:$B$3532,$A8,'Data (Empaneled)'!$J$2:$J$3532,"Yes")/$B8,0) -> 0.33333333 | M8: =IF(SUM(C8:F8)=B8,"OK","MISMATCH") -> OK | N8: =$A8&"|Tier 1" -> Chandigarh|Tier 1 | O8: =$A8&"|Tier 2A" -> Chandigarh|Tier 2A | P8: =$A8&"|Tier 2B" -> Chandigarh|Tier 2B | Q8: =$A8&"|Tier 3" -> Chandigarh|Tier 3
A9: Chhattisgarh | B9: =COUNTIF('Data (Empaneled)'!$B$2:$B$3532,$A9) -> 38 | C9: =COUNTIF('Data (Empaneled)'!$K$2:$K$3532,$N9) -> 0 | D9: =COUNTIF('Data (Empaneled)'!$K$2:$K$3532,$O9) -> 0 | E9: =COUNTIF('Data (Empaneled)'!$K$2:$K$3532,$P9) -> 6 | F9: =COUNTIF('Data (Empaneled)'!$K$2:$K$3532,$Q9) -> 32 | G9: =IFERROR(COUNTIFS('Data (Empaneled)'!$B$2:$B$3532,$A9,'Data (Empaneled)'!$F$2:$F$3532,"Yes")/$B9,0) -> 0.31578947 | H9: =IFERROR(COUNTIFS('Data (Empaneled)'!$B$2:$B$3532,$A9,'Data (Empaneled)'!$G$2:$G$3532,"Yes")/$B9,0) -> 0.34210526 | I9: =IFERROR(COUNTIFS('Data (Empaneled)'!$B$2:$B$3532,$A9,'Data (Empaneled)'!$H$2:$H$3532,"Yes")/$B9,0) -> 0.23684211 | J9: =IFERROR(COUNTIFS('Data (Empaneled)'!$B$2:$B$3532,$A9,'Data (Empaneled)'!$I$2:$I$3532,"Yes")/$B9,0) -> 0.71052632 | K9: =IFERROR(COUNTIFS('Data (Empaneled)'!$B$2:$B$3532,$A9,'Data (Empaneled)'!$J$2:$J$3532,"Yes")/$B9,0) -> 0.42105263 | M9: =IF(SUM(C9:F9)=B9,"OK","MISMATCH") -> OK | N9: =$A9&"|Tier 1" -> Chhattisgarh|Tier 1 | O9: =$A9&"|Tier 2A" -> Chhattisgarh|Tier 2A | P9: =$A9&"|Tier 2B" -> Chhattisgarh|Tier 2B | Q9: =$A9&"|Tier 3" -> Chhattisgarh|Tier 3
A10: Delhi | B10: =COUNTIF('Data (Empaneled)'!$B$2:$B$3532,$A10) -> 72 | C10: =COUNTIF('Data (Empaneled)'!$K$2:$K$3532,$N10) -> 72 | D10: =COUNTIF('Data (Empaneled)'!$K$2:$K$3532,$O10) -> 0 | E10: =COUNTIF('Data (Empaneled)'!$K$2:$K$3532,$P10) -> 0 | F10: =COUNTIF('Data (Empaneled)'!$K$2:$K$3532,$Q10) -> 0 | G10: =IFERROR(COUNTIFS('Data (Empaneled)'!$B$2:$B$3532,$A10,'Data (Empaneled)'!$F$2:$F$3532,"Yes")/$B10,0) -> 0.19444444 | H10: =IFERROR(COUNTIFS('Data (Empaneled)'!$B$2:$B$3532,$A10,'Data (Empaneled)'!$G$2:$G$3532,"Yes")/$B10,0) -> 0.18055556 | I10: =IFERROR(COUNTIFS('Data (Empaneled)'!$B$2:$B$3532,$A10,'Data (Empaneled)'!$H$2:$H$3532,"Yes")/$B10,0) -> 0.41666667 | J10: =IFERROR(COUNTIFS('Data (Empaneled)'!$B$2:$B$3532,$A10,'Data (Empaneled)'!$I$2:$I$3532,"Yes")/$B10,0) -> 0.59722222 | K10: =IFERROR(COUNTIFS('Data (Empaneled)'!$B$2:$B$3532,$A10,'Data (Empaneled)'!$J$2:$J$3532,"Yes")/$B10,0) -> 0.33333333 | M10: =IF(SUM(C10:F10)=B10,"OK","MISMATCH") -> OK | N10: =$A10&"|Tier 1" -> Delhi|Tier 1 | O10: =$A10&"|Tier 2A" -> Delhi|Tier 2A | P10: =$A10&"|Tier 2B" -> Delhi|Tier 2B | Q10: =$A10&"|Tier 3" -> Delhi|Tier 3
A11: Gujarat | B11: =COUNTIF('Data (Empaneled)'!$B$2:$B$3532,$A11) -> 188 | C11: =COUNTIF('Data (Empaneled)'!$K$2:$K$3532,$N11) -> 23 | D11: =COUNTIF('Data (Empaneled)'!$K$2:$K$3532,$O11) -> 113 | E11: =COUNTIF('Data (Empaneled)'!$K$2:$K$3532,$P11) -> 8 | F11: =COUNTIF('Data (Empaneled)'!$K$2:$K$3532,$Q11) -> 44 | G11: =IFERROR(COUNTIFS('Data (Empaneled)'!$B$2:$B$3532,$A11,'Data (Empaneled)'!$F$2:$F$3532,"Yes")/$B11,0) -> 0.24468085 | H11: =IFERROR(COUNTIFS('Data (Empaneled)'!$B$2:$B$3532,$A11,'Data (Empaneled)'!$G$2:$G$3532,"Yes")/$B11,0) -> 0.24468085 | I11: =IFERROR(COUNTIFS('Data (Empaneled)'!$B$2:$B$3532,$A11,'Data (Empaneled)'!$H$2:$H$3532,"Yes")/$B11,0) -> 0.14361702 | J11: =IFERROR(COUNTIFS('Data (Empaneled)'!$B$2:$B$3532,$A11,'Data (Empaneled)'!$I$2:$I$3532,"Yes")/$B11,0) -> 0.41489362 | K11: =IFERROR(COUNTIFS('Data (Empaneled)'!$B$2:$B$3532,$A11,'Data (Empaneled)'!$J$2:$J$3532,"Yes")/$B11,0) -> 0.21808511 | M11: =IF(SUM(C11:F11)=B11,"OK","MISMATCH") -> OK | N11: =$A11&"|Tier 1" -> Gujarat|Tier 1 | O11: =$A11&"|Tier 2A" -> Gujarat|Tier 2A | P11: =$A11&"|Tier 2B" -> Gujarat|Tier 2B | Q11: =$A11&"|Tier 3" -> Gujarat|Tier 3
A12: Haryana | B12: =COUNTIF('Data (Empaneled)'!$B$2:$B$3532,$A12) -> 175 | C12: =COUNTIF('Data (Empaneled)'!$K$2:$K$3532,$N12) -> 28 | D12: =COUNTIF('Data (Empaneled)'!$K$2:$K$3532,$O12) -> 0 | E12: =COUNTIF('Data (Empaneled)'!$K$2:$K$3532,$P12) -> 18 | F12: =COUNTIF('Data (Empaneled)'!$K$2:$K$3532,$Q12) -> 129 | G12: =IFERROR(COUNTIFS('Data (Empaneled)'!$B$2:$B$3532,$A12,'Data (Empaneled)'!$F$2:$F$3532,"Yes")/$B12,0) -> 0.29714286 | H12: =IFERROR(COUNTIFS('Data (Empaneled)'!$B$2:$B$3532,$A12,'Data (Empaneled)'!$G$2:$G$3532,"Yes")/$B12,0) -> 0.23428571 | I12: =IFERROR(COUNTIFS('Data (Empaneled)'!$B$2:$B$3532,$A12,'Data (Empaneled)'!$H$2:$H$3532,"Yes")/$B12,0) -> 0.28571429 | J12: =IFERROR(COUNTIFS('Data (Empaneled)'!$B$2:$B$3532,$A12,'Data (Empaneled)'!$I$2:$I$3532,"Yes")/$B12,0) -> 0.69142857 | K12: =IFERROR(COUNTIFS('Data (Empaneled)'!$B$2:$B$3532,$A12,'Data (Empaneled)'!$J$2:$J$3532,"Yes")/$B12,0) -> 0.36571429 | M12: =IF(SUM(C12:F12)=B12,"OK","MISMATCH") -> OK | N12: =$A12&"|Tier 1" -> Haryana|Tier 1 | O12: =$A12&"|Tier 2A" -> Haryana|Tier 2A | P12: =$A12&"|Tier 2B" -> Haryana|Tier 2B | Q12: =$A12&"|Tier 3" -> Haryana|Tier 3
A13: Himachal Pradesh | B13: =COUNTIF('Data (Empaneled)'!$B$2:$B$3532,$A13) -> 22 | C13: =COUNTIF('Data (Empaneled)'!$K$2:$K$3532,$N13) -> 0 | D13: =COUNTIF('Data (Empaneled)'!$K$2:$K$3532,$O13) -> 0 | E13: =COUNTIF('Data (Empaneled)'!$K$2:$K$3532,$P13) -> 0 | F13: =COUNTIF('Data (Empaneled)'!$K$2:$K$3532,$Q13) -> 22 | G13: =IFERROR(COUNTIFS('Data (Empaneled)'!$B$2:$B$3532,$A13,'Data (Empaneled)'!$F$2:$F$3532,"Yes")/$B13,0) -> 0.090909091 | H13: =IFERROR(COUNTIFS('Data (Empaneled)'!$B$2:$B$3532,$A13,'Data (Empaneled)'!$G$2:$G$3532,"Yes")/$B13,0) -> 0.090909091 | I13: =IFERROR(COUNTIFS('Data (Empaneled)'!$B$2:$B$3532,$A13,'Data (Empaneled)'!$H$2:$H$3532,"Yes")/$B13,0) -> 0.36363636 | J13: =IFERROR(COUNTIFS('Data (Empaneled)'!$B$2:$B$3532,$A13,'Data (Empaneled)'!$I$2:$I$3532,"Yes")/$B13,0) -> 0.54545455 | K13: =IFERROR(COUNTIFS('Data (Empaneled)'!$B$2:$B$3532,$A13,'Data (Empaneled)'!$J$2:$J$3532,"Yes")/$B13,0) -> 0.31818182 | M13: =IF(SUM(C13:F13)=B13,"OK","MISMATCH") -> OK | N13: =$A13&"|Tier 1" -> Himachal Pradesh|Tier 1 | O13: =$A13&"|Tier 2A" -> Himachal Pradesh|Tier 2A | P13: =$A13&"|Tier 2B" -> Himachal Pradesh|Tier 2B | Q13: =$A13&"|Tier 3" -> Himachal Pradesh|Tier 3
A14: Jammu & Kashmir | B14: =COUNTIF('Data (Empaneled)'!$B$2:$B$3532,$A14) -> 8 | C14: =COUNTIF('Data (Empaneled)'!$K$2:$K$3532,$N14) -> 0 | D14: =COUNTIF('Data (Empaneled)'!$K$2:$K$3532,$O14) -> 0 | E14: =COUNTIF('Data (Empaneled)'!$K$2:$K$3532,$P14) -> 5 | F14: =COUNTIF('Data (Empaneled)'!$K$2:$K$3532,$Q14) -> 3 | G14: =IFERROR(COUNTIFS('Data (Empaneled)'!$B$2:$B$3532,$A14,'Data (Empaneled)'!$F$2:$F$3532,"Yes")/$B14,0) -> 0.625 | H14: =IFERROR(COUNTIFS('Data (Empaneled)'!$B$2:$B$3532,$A14,'Data (Empaneled)'!$G$2:$G$3532,"Yes")/$B14,0) -> 0.375 | I14: =IFERROR(COUNTIFS('Data (Empaneled)'!$B$2:$B$3532,$A14,'Data (Empaneled)'!$H$2:$H$3532,"Yes")/$B14,0) -> 0.75 | J14: =IFERROR(COUNTIFS('Data (Empaneled)'!$B$2:$B$3532,$A14,'Data (Empaneled)'!$I$2:$I$3532,"Yes")/$B14,0) -> 0.625 | K14: =IFERROR(COUNTIFS('Data (Empaneled)'!$B$2:$B$3532,$A14,'Data (Empaneled)'!$J$2:$J$3532,"Yes")/$B14,0) -> 0.375 | M14: =IF(SUM(C14:F14)=B14,"OK","MISMATCH") -> OK | N14: =$A14&"|Tier 1" -> Jammu & Kashmir|Tier 1 | O14: =$A14&"|Tier 2A" -> Jammu & Kashmir|Tier 2A | P14: =$A14&"|Tier 2B" -> Jammu & Kashmir|Tier 2B | Q14: =$A14&"|Tier 3" -> Jammu & Kashmir|Tier 3
A15: Jharkhand | B15: =COUNTIF('Data (Empaneled)'!$B$2:$B$3532,$A15) -> 23 | C15: =COUNTIF('Data (Empaneled)'!$K$2:$K$3532,$N15) -> 0 | D15: =COUNTIF('Data (Empaneled)'!$K$2:$K$3532,$O15) -> 0 | E15: =COUNTIF('Data (Empaneled)'!$K$2:$K$3532,$P15) -> 18 | F15: =COUNTIF('Data (Empaneled)'!$K$2:$K$3532,$Q15) -> 5 | G15: =IFERROR(COUNTIFS('Data (Empaneled)'!$B$2:$B$3532,$A15,'Data (Empaneled)'!$F$2:$F$3532,"Yes")/$B15,0) -> 0.34782609 | H15: =IFERROR(COUNTIFS('Data (Empaneled)'!$B$2:$B$3532,$A15,'Data (Empaneled)'!$G$2:$G$3532,"Yes")/$B15,0) -> 0.34782609 | I15: =IFERROR(COUNTIFS('Data (Empaneled)'!$B$2:$B$3532,$A15,'Data (Empaneled)'!$H$2:$H$3532,"Yes")/$B15,0) -> 0.43478261 | J15: =IFERROR(COUNTIFS('Data (Empaneled)'!$B$2:$B$3532,$A15,'Data (Empaneled)'!$I$2:$I$3532,"Yes")/$B15,0) -> 0.65217391 | K15: =IFERROR(COUNTIFS('Data (Empaneled)'!$B$2:$B$3532,$A15,'Data (Empaneled)'!$J$2:$J$3532,"Yes")/$B15,0) -> 0.39130435 | M15: =IF(SUM(C15:F15)=B15,"OK","MISMATCH") -> OK | N15: =$A15&"|Tier 1" -> Jharkhand|Tier 1 | O15: =$A15&"|Tier 2A" -> Jharkhand|Tier 2A | P15: =$A15&"|Tier 2B" -> Jharkhand|Tier 2B | Q15: =$A15&"|Tier 3" -> Jharkhand|Tier 3
A16: Karnataka | B16: =COUNTIF('Data (Empaneled)'!$B$2:$B$3532,$A16) -> 164 | C16: =COUNTIF('Data (Empaneled)'!$K$2:$K$3532,$N16) -> 25 | D16: =COUNTIF('Data (Empaneled)'!$K$2:$K$3532,$O16) -> 0 | E16: =COUNTIF('Data (Empaneled)'!$K$2:$K$3532,$P16) -> 28 | F16: =COUNTIF('Data (Empaneled)'!$K$2:$K$3532,$Q16) -> 111 | G16: =IFERROR(COUNTIFS('Data (Empaneled)'!$B$2:$B$3532,$A16,'Data (Empaneled)'!$F$2:$F$3532,"Yes")/$B16,0) -> 0.29268293 | H16: =IFERROR(COUNTIFS('Data (Empaneled)'!$B$2:$B$3532,$A16,'Data (Empaneled)'!$G$2:$G$3532,"Yes")/$B16,0) -> 0.33536585 | I16: =IFERROR(COUNTIFS('Data (Empaneled)'!$B$2:$B$3532,$A16,'Data (Empaneled)'!$H$2:$H$3532,"Yes")/$B16,0) -> 0.38414634 | J16: =IFERROR(COUNTIFS('Data (Empaneled)'!$B$2:$B$3532,$A16,'Data (Empaneled)'!$I$2:$I$3532,"Yes")/$B16,0) -> 0.68902439 | K16: =IFERROR(COUNTIFS('Data (Empaneled)'!$B$2:$B$3532,$A16,'Data (Empaneled)'!$J$2:$J$3532,"Yes")/$B16,0) -> 0.40853659 | M16: =IF(SUM(C16:F16)=B16,"OK","MISMATCH") -> OK | N16: =$A16&"|Tier 1" -> Karnataka|Tier 1 | O16: =$A16&"|Tier 2A" -> Karnataka|Tier 2A | P16: =$A16&"|Tier 2B" -> Karnataka|Tier 2B | Q16: =$A16&"|Tier 3" -> Karnataka|Tier 3
... A29: West Bengal | B29: =COUNTIF('Data (Empaneled)'!$B$2:$B$3532,$A29) -> 358 | C29: =COUNTIF('Data (Empaneled)'!$K$2:$K$3532,$N29) -> 56 | D29: =COUNTIF('Data (Empaneled)'!$K$2:$K$3532,$O29) -> 0 | E29: =COUNTIF('Data (Empaneled)'!$K$2:$K$3532,$P29) -> 12 | F29: =COUNTIF('Data (Empaneled)'!$K$2:$K$3532,$Q29) -> 290 | G29: =IFERROR(COUNTIFS('Data (Empaneled)'!$B$2:$B$3532,$A29,'Data (Empaneled)'!$F$2:$F$3532,"Yes")/$B29,0) -> 0.54748603 | H29: =IFERROR(COUNTIFS('Data (Empaneled)'!$B$2:$B$3532,$A29,'Data (Empaneled)'!$G$2:$G$3532,"Yes")/$B29,0) -> 0.54469274 | I29: =IFERROR(COUNTIFS('Data (Empaneled)'!$B$2:$B$3532,$A29,'Data (Empaneled)'!$H$2:$H$3532,"Yes")/$B29,0) -> 0.44413408 | J29: =IFERROR(COUNTIFS('Data (Empaneled)'!$B$2:$B$3532,$A29,'Data (Empaneled)'!$I$2:$I$3532,"Yes")/$B29,0) -> 0.71787709 | K29: =IFERROR(COUNTIFS('Data (Empaneled)'!$B$2:$B$3532,$A29,'Data (Empaneled)'!$J$2:$J$3532,"Yes")/$B29,0) -> 0.49441341 | M29: =IF(SUM(C29:F29)=B29,"OK","MISMATCH") -> OK | N29: =$A29&"|Tier 1" -> West Bengal|Tier 1 | O29: =$A29&"|Tier 2A" -> West Bengal|Tier 2A | P29: =$A29&"|Tier 2B" -> West Bengal|Tier 2B | Q29: =$A29&"|Tier 3" -> West Bengal|Tier 3
A30: NATIONAL TOTAL | B30: =SUM(B5:B29) -> 3530 | C30: =SUM(C5:C29) -> 543 | D30: =SUM(D5:D29) -> 347 | E30: =SUM(E5:E29) -> 687 | F30: =SUM(F5:F29) -> 1953 | G30: =IFERROR(COUNTIF('Data (Empaneled)'!$F$2:$F$3532,"Yes")/$B30,0) -> 0.34164306 | H30: =IFERROR(COUNTIF('Data (Empaneled)'!$G$2:$G$3532,"Yes")/$B30,0) -> 0.3101983 | I30: =IFERROR(COUNTIF('Data (Empaneled)'!$H$2:$H$3532,"Yes")/$B30,0) -> 0.3470255 | J30: =IFERROR(COUNTIF('Data (Empaneled)'!$I$2:$I$3532,"Yes")/$B30,0) -> 0.6203966 | K30: =IFERROR(COUNTIF('Data (Empaneled)'!$J$2:$J$3532,"Yes")/$B30,0) -> 0.3325779 | M30: =IF(SUM(C30:F30)=B30,"OK","MISMATCH") -> OK
A32: Tier definitions — Tier 1: Ahmedabad, Bangalore, Chennai, Delhi, Gurugram, Hyderabad, Kolkata, Mumbai, Noida, Pune. Tier 2A: 14 cities. Tier 2B: 67 cities. Tier 3: all other locations.
A33: Specialty % = share of that state's empaneled hospitals declaring the specialty in their CEP registration. All figures are live formulas over the "Data (Empaneled)" sheet.

Sheet City-wise Mapping
A1: City-wise Empaneled Hospital Mapping with Specialty Bifurcation
A4: State | B4: City | C4: Tier | D4: Hospital Count | E4: Cardiology | F4: Oncology | G4: Ophthalmology | H4: Maternal Health (OBGY) | I4: Neonatology | J4: Cardiology2 | K4: Column3 | L4: Oncology4 | M4: Ophthalmology5 | N4: Maternal Health (OBGY)6 | O4: Neonatology7
A5: Maharashtra | B5: Mumbai | C5: Tier 1 | D5: =COUNTIF('Data (Empaneled)'!$L$2:$L$3532,$K5) -> 50 | E5: =COUNTIF('Data (Empaneled)'!$M$2:$M$3532,$K5)&"/"&$D5 -> 15/50 | F5: =COUNTIF('Data (Empaneled)'!$N$2:$N$3532,$K5)&"/"&$D5 -> 17/50 | G5: =COUNTIF('Data (Empaneled)'!$O$2:$O$3532,$K5)&"/"&$D5 -> 28/50 | H5: =COUNTIF('Data (Empaneled)'!$P$2:$P$3532,$K5)&"/"&$D5 -> 18/50 | I5: =COUNTIF('Data (Empaneled)'!$Q$2:$Q$3532,$K5)&"/"&$D5 -> 5/50 | J5: =LEFT(E5, FIND("/", E5)-1) + 0 -> 15 | K5: =$A5&"|"&$B5 -> Maharashtra|Mumbai | L5: =LEFT(F5, FIND("/", F5)-1) + 0 -> 17 | M5: =LEFT(G5, FIND("/", G5)-1) + 0 -> 28 | N5: =LEFT(H5, FIND("/", H5)-1) + 0 -> 18 | O5: =LEFT(I5,FIND("/",I5)-1)+0 -> 5
A6: Telangana | B6: Hyderabad | C6: Tier 1 | D6: =COUNTIF('Data (Empaneled)'!$L$2:$L$3532,$K6) -> 92 | E6: =COUNTIF('Data (Empaneled)'!$M$2:$M$3532,$K6)&"/"&$D6 -> 37/92 | F6: =COUNTIF('Data (Empaneled)'!$N$2:$N$3532,$K6)&"/"&$D6 -> 25/92 | G6: =COUNTIF('Data (Empaneled)'!$O$2:$O$3532,$K6)&"/"&$D6 -> 27/92 | H6: =COUNTIF('Data (Empaneled)'!$P$2:$P$3532,$K6)&"/"&$D6 -> 65/92 | I6: =COUNTIF('Data (Empaneled)'!$Q$2:$Q$3532,$K6)&"/"&$D6 -> 41/92 | J6: =LEFT(E6, FIND("/", E6)-1) + 0 -> 37 | K6: =$A6&"|"&$B6 -> Telangana|Hyderabad | L6: =LEFT(F6, FIND("/", F6)-1) + 0 -> 25 | M6: =LEFT(G6, FIND("/", G6)-1) + 0 -> 27 | N6: =LEFT(H6, FIND("/", H6)-1) + 0 -> 65 | O6: =LEFT(I6,FIND("/",I6)-1)+0 -> 41
A7: Delhi | B7: Delhi | C7: Tier 1 | D7: =COUNTIF('Data (Empaneled)'!$L$2:$L$3532,$K7) -> 72 | E7: =COUNTIF('Data (Empaneled)'!$M$2:$M$3532,$K7)&"/"&$D7 -> 14/72 | F7: =COUNTIF('Data (Empaneled)'!$N$2:$N$3532,$K7)&"/"&$D7 -> 13/72 | G7: =COUNTIF('Data (Empaneled)'!$O$2:$O$3532,$K7)&"/"&$D7 -> 30/72 | H7: =COUNTIF('Data (Empaneled)'!$P$2:$P$3532,$K7)&"/"&$D7 -> 43/72 | I7: =COUNTIF('Data (Empaneled)'!$Q$2:$Q$3532,$K7)&"/"&$D7 -> 24/72 | J7: =LEFT(E7, FIND("/", E7)-1) + 0 -> 14 | K7: =$A7&"|"&$B7 -> Delhi|Delhi | L7: =LEFT(F7, FIND("/", F7)-1) + 0 -> 13 | M7: =LEFT(G7, FIND("/", G7)-1) + 0 -> 30 | N7: =LEFT(H7, FIND("/", H7)-1) + 0 -> 43 | O7: =LEFT(I7,FIND("/",I7)-1)+0 -> 24
A8: West Bengal | B8: Kolkata | C8: Tier 1 | D8: =COUNTIF('Data (Empaneled)'!$L$2:$L$3532,$K8) -> 56 | E8: =COUNTIF('Data (Empaneled)'!$M$2:$M$3532,$K8)&"/"&$D8 -> 29/56 | F8: =COUNTIF('Data (Empaneled)'!$N$2:$N$3532,$K8)&"/"&$D8 -> 32/56 | G8: =COUNTIF('Data (Empaneled)'!$O$2:$O$3532,$K8)&"/"&$D8 -> 32/56 | H8: =COUNTIF('Data (Empaneled)'!$P$2:$P$3532,$K8)&"/"&$D8 -> 32/56 | I8: =COUNTIF('Data (Empaneled)'!$Q$2:$Q$3532,$K8)&"/"&$D8 -> 17/56 | J8: =LEFT(E8, FIND("/", E8)-1) + 0 -> 29 | K8: =$A8&"|"&$B8 -> West Bengal|Kolkata | L8: =LEFT(F8, FIND("/", F8)-1) + 0 -> 32 | M8: =LEFT(G8, FIND("/", G8)-1) + 0 -> 32 | N8: =LEFT(H8, FIND("/", H8)-1) + 0 -> 32 | O8: =LEFT(I8,FIND("/",I8)-1)+0 -> 17
A9: Maharashtra | B9: Pune | C9: Tier 1 | D9: =COUNTIF('Data (Empaneled)'!$L$2:$L$3532,$K9) -> 156 | E9: =COUNTIF('Data (Empaneled)'!$M$2:$M$3532,$K9)&"/"&$D9 -> 74/156 | F9: =COUNTIF('Data (Empaneled)'!$N$2:$N$3532,$K9)&"/"&$D9 -> 78/156 | G9: =COUNTIF('Data (Empaneled)'!$O$2:$O$3532,$K9)&"/"&$D9 -> 52/156 | H9: =COUNTIF('Data (Empaneled)'!$P$2:$P$3532,$K9)&"/"&$D9 -> 96/156 | I9: =COUNTIF('Data (Empaneled)'!$Q$2:$Q$3532,$K9)&"/"&$D9 -> 42/156 | J9: =LEFT(E9, FIND("/", E9)-1) + 0 -> 74 | K9: =$A9&"|"&$B9 -> Maharashtra|Pune | L9: =LEFT(F9, FIND("/", F9)-1) + 0 -> 78 | M9: =LEFT(G9, FIND("/", G9)-1) + 0 -> 52 | N9: =LEFT(H9, FIND("/", H9)-1) + 0 -> 96 | O9: =LEFT(I9,FIND("/",I9)-1)+0 -> 42
A10: Haryana | B10: Gurugram | C10: Tier 1 | D10: =COUNTIF('Data (Empaneled)'!$L$2:$L$3532,$K10) -> 28 | E10: =COUNTIF('Data (Empaneled)'!$M$2:$M$3532,$K10)&"/"&$D10 -> 11/28 | F10: =COUNTIF('Data (Empaneled)'!$N$2:$N$3532,$K10)&"/"&$D10 -> 11/28 | G10: =COUNTIF('Data (Empaneled)'!$O$2:$O$3532,$K10)&"/"&$D10 -> 13/28 | H10: =COUNTIF('Data (Empaneled)'!$P$2:$P$3532,$K10)&"/"&$D10 -> 17/28 | I10: =COUNTIF('Data (Empaneled)'!$Q$2:$Q$3532,$K10)&"/"&$D10 -> 13/28 | J10: =LEFT(E10, FIND("/", E10)-1) + 0 -> 11 | K10: =$A10&"|"&$B10 -> Haryana|Gurugram | L10: =LEFT(F10, FIND("/", F10)-1) + 0 -> 11 | M10: =LEFT(G10, FIND("/", G10)-1) + 0 -> 13 | N10: =LEFT(H10, FIND("/", H10)-1) + 0 -> 17 | O10: =LEFT(I10,FIND("/",I10)-1)+0 -> 13
A11: Karnataka | B11: Bangalore | C11: Tier 1 | D11: =COUNTIF('Data (Empaneled)'!$L$2:$L$3532,$K11) -> 25 | E11: =COUNTIF('Data (Empaneled)'!$M$2:$M$3532,$K11)&"/"&$D11 -> 7/25 | F11: =COUNTIF('Data (Empaneled)'!$N$2:$N$3532,$K11)&"/"&$D11 -> 12/25 | G11: =COUNTIF('Data (Empaneled)'!$O$2:$O$3532,$K11)&"/"&$D11 -> 13/25 | H11: =COUNTIF('Data (Empaneled)'!$P$2:$P$3532,$K11)&"/"&$D11 -> 15/25 | I11: =COUNTIF('Data (Empaneled)'!$Q$2:$Q$3532,$K11)&"/"&$D11 -> 10/25 | J11: =LEFT(E11, FIND("/", E11)-1) + 0 -> 7 | K11: =$A11&"|"&$B11 -> Karnataka|Bangalore | L11: =LEFT(F11, FIND("/", F11)-1) + 0 -> 12 | M11: =LEFT(G11, FIND("/", G11)-1) + 0 -> 13 | N11: =LEFT(H11, FIND("/", H11)-1) + 0 -> 15 | O11: =LEFT(I11,FIND("/",I11)-1)+0 -> 10
A12: Uttar Pradesh | B12: Noida | C12: Tier 1 | D12: =COUNTIF('Data (Empaneled)'!$L$2:$L$3532,$K12) -> 24 | E12: =COUNTIF('Data (Empaneled)'!$M$2:$M$3532,$K12)&"/"&$D12 -> 9/24 | F12: =COUNTIF('Data (Empaneled)'!$N$2:$N$3532,$K12)&"/"&$D12 -> 10/24 | G12: =COUNTIF('Data (Empaneled)'!$O$2:$O$3532,$K12)&"/"&$D12 -> 14/24 | H12: =COUNTIF('Data (Empaneled)'!$P$2:$P$3532,$K12)&"/"&$D12 -> 17/24 | I12: =COUNTIF('Data (Empaneled)'!$Q$2:$Q$3532,$K12)&"/"&$D12 -> 14/24 | J12: =LEFT(E12, FIND("/", E12)-1) + 0 -> 9 | K12: =$A12&"|"&$B12 -> Uttar Pradesh|Noida | L12: =LEFT(F12, FIND("/", F12)-1) + 0 -> 10 | M12: =LEFT(G12, FIND("/", G12)-1) + 0 -> 14 | N12: =LEFT(H12, FIND("/", H12)-1) + 0 -> 17 | O12: =LEFT(I12,FIND("/",I12)-1)+0 -> 14
A13: Gujarat | B13: Ahmedabad | C13: Tier 1 | D13: =COUNTIF('Data (Empaneled)'!$L$2:$L$3532,$K13) -> 23 | E13: =COUNTIF('Data (Empaneled)'!$M$2:$M$3532,$K13)&"/"&$D13 -> 5/23 | F13: =COUNTIF('Data (Empaneled)'!$N$2:$N$3532,$K13)&"/"&$D13 -> 10/23 | G13: =COUNTIF('Data (Empaneled)'!$O$2:$O$3532,$K13)&"/"&$D13 -> 3/23 | H13: =COUNTIF('Data (Empaneled)'!$P$2:$P$3532,$K13)&"/"&$D13 -> 12/23 | I13: =COUNTIF('Data (Empaneled)'!$Q$2:$Q$3532,$K13)&"/"&$D13 -> 6/23 | J13: =LEFT(E13, FIND("/", E13)-1) + 0 -> 5 | K13: =$A13&"|"&$B13 -> Gujarat|Ahmedabad | L13: =LEFT(F13, FIND("/", F13)-1) + 0 -> 10 | M13: =LEFT(G13, FIND("/", G13)-1) + 0 -> 3 | N13: =LEFT(H13, FIND("/", H13)-1) + 0 -> 12 | O13: =LEFT(I13,FIND("/",I13)-1)+0 -> 6
A14: Tamil Nadu | B14: Chennai | C14: Tier 1 | D14: =COUNTIF('Data (Empaneled)'!$L$2:$L$3532,$K14) -> 17 | E14: =COUNTIF('Data (Empaneled)'!$M$2:$M$3532,$K14)&"/"&$D14 -> 12/17 | F14: =COUNTIF('Data (Empaneled)'!$N$2:$N$3532,$K14)&"/"&$D14 -> 12/17 | G14: =COUNTIF('Data (Empaneled)'!$O$2:$O$3532,$K14)&"/"&$D14 -> 4/17 | H14: =COUNTIF('Data (Empaneled)'!$P$2:$P$3532,$K14)&"/"&$D14 -> 15/17 | I14: =COUNTIF('Data (Empaneled)'!$Q$2:$Q$3532,$K14)&"/"&$D14 -> 8/17 | J14: =LEFT(E14, FIND("/", E14)-1) + 0 -> 12 | K14: =$A14&"|"&$B14 -> Tamil Nadu|Chennai | L14: =LEFT(F14, FIND("/", F14)-1) + 0 -> 12 | M14: =LEFT(G14, FIND("/", G14)-1) + 0 -> 4 | N14: =LEFT(H14, FIND("/", H14)-1) + 0 -> 15 | O14: =LEFT(I14,FIND("/",I14)-1)+0 -> 8
A15: Gujarat | B15: Surat | C15: Tier 2A | D15: =COUNTIF('Data (Empaneled)'!$L$2:$L$3532,$K15) -> 59 | E15: =COUNTIF('Data (Empaneled)'!$M$2:$M$3532,$K15)&"/"&$D15 -> 14/59 | F15: =COUNTIF('Data (Empaneled)'!$N$2:$N$3532,$K15)&"/"&$D15 -> 15/59 | G15: =COUNTIF('Data (Empaneled)'!$O$2:$O$3532,$K15)&"/"&$D15 -> 4/59 | H15: =COUNTIF('Data (Empaneled)'!$P$2:$P$3532,$K15)&"/"&$D15 -> 18/59 | I15: =COUNTIF('Data (Empaneled)'!$Q$2:$Q$3532,$K15)&"/"&$D15 -> 19/59 | J15: =LEFT(E15, FIND("/", E15)-1) + 0 -> 14 | K15: =$A15&"|"&$B15 -> Gujarat|Surat | L15: =LEFT(F15, FIND("/", F15)-1) + 0 -> 15 | M15: =LEFT(G15, FIND("/", G15)-1) + 0 -> 4 | N15: =LEFT(H15, FIND("/", H15)-1) + 0 -> 18 | O15: =LEFT(I15,FIND("/",I15)-1)+0 -> 19
A16: Bihar | B16: Patna | C16: Tier 2A | D16: =COUNTIF('Data (Empaneled)'!$L$2:$L$3532,$K16) -> 55 | E16: =COUNTIF('Data (Empaneled)'!$M$2:$M$3532,$K16)&"/"&$D16 -> 32/55 | F16: =COUNTIF('Data (Empaneled)'!$N$2:$N$3532,$K16)&"/"&$D16 -> 24/55 | G16: =COUNTIF('Data (Empaneled)'!$O$2:$O$3532,$K16)&"/"&$D16 -> 23/55 | H16: =COUNTIF('Data (Empaneled)'!$P$2:$P$3532,$K16)&"/"&$D16 -> 37/55 | I16: =COUNTIF('Data (Empaneled)'!$Q$2:$Q$3532,$K16)&"/"&$D16 -> 27/55 | J16: =LEFT(E16, FIND("/", E16)-1) + 0 -> 32 | K16: =$A16&"|"&$B16 -> Bihar|Patna | L16: =LEFT(F16, FIND("/", F16)-1) + 0 -> 24 | M16: =LEFT(G16, FIND("/", G16)-1) + 0 -> 23 | N16: =LEFT(H16, FIND("/", H16)-1) + 0 -> 37 | O16: =LEFT(I16,FIND("/",I16)-1)+0 -> 27
... A933: West Bengal | B933: Uttar Dinajpur | C933: Tier 3 | D933: =COUNTIF('Data (Empaneled)'!$L$2:$L$3532,$K933) -> 1 | E933: =COUNTIF('Data (Empaneled)'!$M$2:$M$3532,$K933)&"/"&$D933 -> 0/1 | F933: =COUNTIF('Data (Empaneled)'!$N$2:$N$3532,$K933)&"/"&$D933 -> 0/1 | G933: =COUNTIF('Data (Empaneled)'!$O$2:$O$3532,$K933)&"/"&$D933 -> 0/1 | H933: =COUNTIF('Data (Empaneled)'!$P$2:$P$3532,$K933)&"/"&$D933 -> 0/1 | I933: =COUNTIF('Data (Empaneled)'!$Q$2:$Q$3532,$K933)&"/"&$D933 -> 0/1 | J933: =LEFT(E933, FIND("/", E933)-1) + 0 -> 0 | K933: =$A933&"|"&$B933 -> West Bengal|Uttar Dinajpur | L933: =LEFT(F933, FIND("/", F933)-1) + 0 -> 0 | M933: =LEFT(G933, FIND("/", G933)-1) + 0 -> 0 | N933: =LEFT(H933, FIND("/", H933)-1) + 0 -> 0 | O933: =LEFT(I933,FIND("/",I933)-1)+0 -> 0
J934: =SUM(J5:J933) -> 1206 | L934: =SUM(L5:L933) -> 1095 | M934: =SUM(M5:M933) -> 1225 | N934: =SUM(N5:N933) -> 2190 | O934: =SUM(O5:O933) -> 1174
A938: TOTAL | D938: =SUM(D5:D933) -> 3530
A939: Specialty columns read "hospitals offering / total in city". All figures are live formulas over the "Data (Empaneled)" sheet.
J941: =J934/D938 -> 0.34164306 | L941: =L934/D938 -> 0.3101983 | M941: =M934/D938 -> 0.3470255 | N941: =N934/D938 -> 0.6203966 | O941: =O934/D938 -> 0.3325779

Sheet Sheet3

Sheet Sheet4

Sheet Sheet2
A1: ='Data (Empaneled)'!L1 -> Key: State|City | B1: BAREILLY | C1: ='Data (Empaneled)'!B1 -> State | D1: ='Data (Empaneled)'!C1 -> City (as entered) | E1: ='Data (Empaneled)'!D1 -> City (cleaned) | F1: ='Data (Empaneled)'!E1 -> Tier | G1: ='Data (Empaneled)'!F1 -> Cardiology | H1: ='Data (Empaneled)'!G1 -> Oncology | I1: ='Data (Empaneled)'!H1 -> Ophthalmology | J1: ='Data (Empaneled)'!I1 -> Maternal Health (OBGY) | ... Z1: ='Data (Empaneled)'!Y1 -> 0
A2: ='Data (Empaneled)'!L2 -> West Bengal|Pgs N | B2: ='Data (Empaneled)'!A2 -> PANACEA NURSING HOME | C2: ='Data (Empaneled)'!B2 -> West Bengal | D2: ='Data (Empaneled)'!C2 -> 24 PGS (N) | E2: ='Data (Empaneled)'!D2 -> Pgs N | F2: ='Data (Empaneled)'!E2 -> Tier 3 | G2: ='Data (Empaneled)'!F2 -> Yes | H2: ='Data (Empaneled)'!G2 -> Yes | I2: ='Data (Empaneled)'!H2 -> No | ... Z2: ='Data (Empaneled)'!Y2 -> 0
A3: ='Data (Empaneled)'!L3 -> West Bengal|Pgs S | B3: ='Data (Empaneled)'!A3 -> THE SAHARARHAT JIS HOSPITAL | C3: ='Data (Empaneled)'!B3 -> West Bengal | D3: ='Data (Empaneled)'!C3 -> 24 PGS (S) | E3: ='Data (Empaneled)'!D3 -> Pgs S | F3: ='Data (Empaneled)'!E3 -> Tier 3 | G3: ='Data (Empaneled)'!F3 -> Yes | H3: ='Data (Empaneled)'!G3 -> Yes | I3: ='Data (Empaneled)'!H3 -> No | ... Z3: ='Data (Empaneled)'!Y3 -> 0
A4: ='Data (Empaneled)'!L4 -> Madhya Pradesh|Satna | B4: ='Data (Empaneled)'!A4 -> Pooja Critical Care Neuro and Trauma Hospital | C4: ='Data (Empaneled)'!B4 -> Madhya Pradesh | D4: ='Data (Empaneled)'!C4 -> 485001 | E4: ='Data (Empaneled)'!D4 -> Satna | F4: ='Data (Empaneled)'!E4 -> Tier 3 | G4: ='Data (Empaneled)'!F4 -> No | H4: ='Data (Empaneled)'!G4 -> No | I4: ='Data (Empaneled)'!H4 -> Yes | ... Z4: ='Data (Empaneled)'!Y4 -> 0
A5: ='Data (Empaneled)'!L5 -> West Bengal|Tamluk | B5: ='Data (Empaneled)'!A5 -> THE LIFE CARE | C5: ='Data (Empaneled)'!B5 -> West Bengal | D5: ='Data (Empaneled)'!C5 -> 721636 | E5: ='Data (Empaneled)'!D5 -> Tamluk | F5: ='Data (Empaneled)'!E5 -> Tier 3 | G5: ='Data (Empaneled)'!F5 -> No | H5: ='Data (Empaneled)'!G5 -> Yes | I5: ='Data (Empaneled)'!H5 -> No | ... Z5: ='Data (Empaneled)'!Y5 -> 0
A6: ='Data (Empaneled)'!L6 -> Madhya Pradesh|Jabalpur | B6: ='Data (Empaneled)'!A6 -> SUDHA MULTISPECIALTY HOSPITAL AND HIGH-RISK PREGNANCY CENTRE | C6: ='Data (Empaneled)'!B6 -> Madhya Pradesh | D6: ='Data (Empaneled)'!C6 -> 837 GOL BAZARJABALPUR MADHYAPRADESH 482002 | E6: ='Data (Empaneled)'!D6 -> Jabalpur | F6: ='Data (Empaneled)'!E6 -> Tier 2B | G6: ='Data (Empaneled)'!F6 -> No | H6: ='Data (Empaneled)'!G6 -> No | I6: ='Data (Empaneled)'!H6 -> Yes | ... Z6: ='Data (Empaneled)'!Y6 -> 0
A7: ='Data (Empaneled)'!L7 -> Punjab|Abohar | B7: ='Data (Empaneled)'!A7 -> ANGEL HOSPITAL (A unit of SehatMitra Healthtech Private Limited) | C7: ='Data (Empaneled)'!B7 -> Punjab | D7: ='Data (Empaneled)'!C7 -> ABOHAR | E7: ='Data (Empaneled)'!D7 -> Abohar | F7: ='Data (Empaneled)'!E7 -> Tier 3 | G7: ='Data (Empaneled)'!F7 -> No | H7: ='Data (Empaneled)'!G7 -> Yes | I7: ='Data (Empaneled)'!H7 -> Yes | ... Z7: ='Data (Empaneled)'!Y7 -> 0
A8: ='Data (Empaneled)'!L8 -> Telangana|Addanki | B8: ='Data (Empaneled)'!A8 -> SATYAVATHI EYE HOSPITAL | C8: ='Data (Empaneled)'!B8 -> Telangana | D8: ='Data (Empaneled)'!C8 -> ADDANKI | E8: ='Data (Empaneled)'!D8 -> Addanki | F8: ='Data (Empaneled)'!E8 -> Tier 3 | G8: ='Data (Empaneled)'!F8 -> No | H8: ='Data (Empaneled)'!G8 -> No | I8: ='Data (Empaneled)'!H8 -> No | ... Z8: ='Data (Empaneled)'!Y8 -> 0
A9: ='Data (Empaneled)'!L9 -> Telangana|Adilabad | B9: ='Data (Empaneled)'!A9 -> ARK HOSPITALS | C9: ='Data (Empaneled)'!B9 -> Telangana | D9: ='Data (Empaneled)'!C9 -> adilabad | E9: ='Data (Empaneled)'!D9 -> Adilabad | F9: ='Data (Empaneled)'!E9 -> Tier 3 | G9: ='Data (Empaneled)'!F9 -> No | H9: ='Data (Empaneled)'!G9 -> No | I9: ='Data (Empaneled)'!H9 -> No | ... Z9: ='Data (Empaneled)'!Y9 -> 0
A10: ='Data (Empaneled)'!L10 -> Telangana|Adilabad | B10: ='Data (Empaneled)'!A10 -> KARTIKEYA HOSPITAL | C10: ='Data (Empaneled)'!B10 -> Telangana | D10: ='Data (Empaneled)'!C10 -> ADILABAD | E10: ='Data (Empaneled)'!D10 -> Adilabad | F10: ='Data (Empaneled)'!E10 -> Tier 3 | G10: ='Data (Empaneled)'!F10 -> No | H10: ='Data (Empaneled)'!G10 -> No | I10: ='Data (Empaneled)'!H10 -> No | ... Z10: ='Data (Empaneled)'!Y10 -> 0
A11: ='Data (Empaneled)'!L11 -> Telangana|Adilabad | B11: ='Data (Empaneled)'!A11 -> SURAKSHA CHILDRENS HOSPITAL | C11: ='Data (Empaneled)'!B11 -> Telangana | D11: ='Data (Empaneled)'!C11 -> ADILABAD | E11: ='Data (Empaneled)'!D11 -> Adilabad | F11: ='Data (Empaneled)'!E11 -> Tier 3 | G11: ='Data (Empaneled)'!F11 -> No | H11: ='Data (Empaneled)'!G11 -> No | I11: ='Data (Empaneled)'!H11 -> No | ... Z11: ='Data (Empaneled)'!Y11 -> 0
A12: ='Data (Empaneled)'!L12 -> Andhra Pradesh|Adoni | B12: ='Data (Empaneled)'!A12 -> ADITYA NURSING HOME | C12: ='Data (Empaneled)'!B12 -> Andhra Pradesh | D12: ='Data (Empaneled)'!C12 -> ADONI | E12: ='Data (Empaneled)'!D12 -> Adoni | F12: ='Data (Empaneled)'!E12 -> Tier 3 | G12: ='Data (Empaneled)'!F12 -> No | H12: ='Data (Empaneled)'!G12 -> No | I12: ='Data (Empaneled)'!H12 -> No | ... Z12: ='Data (Empaneled)'!Y12 -> 0
A13: ='Data (Empaneled)'!L13 -> Kerala|Adoor | B13: ='Data (Empaneled)'!A13 -> MOUNT ZION MEDICAL COLLEGE HOSPITAL | C13: ='Data (Empaneled)'!B13 -> Kerala | D13: ='Data (Empaneled)'!C13 -> ADOOR | E13: ='Data (Empaneled)'!D13 -> Adoor | F13: ='Data (Empaneled)'!E13 -> Tier 3 | G13: ='Data (Empaneled)'!F13 -> Yes | H13: ='Data (Empaneled)'!G13 -> Yes | I13: ='Data (Empaneled)'!H13 -> Yes | ... Z13: ='Data (Empaneled)'!Y13 -> 0
... A2205: ='Data (Empaneled)'!L2205 -> Maharashtra|Narayangaon Pune | B2205: ='Data (Empaneled)'!A2205 -> Dr. Manohar Dhole Medical Foundation | C2205: ='Data (Empaneled)'!B2205 -> Maharashtra | D2205: ='Data (Empaneled)'!C2205 -> Narayangaon,pune | E2205: ='Data (Empaneled)'!D2205 -> Narayangaon Pune | F2205: ='Data (Empaneled)'!E2205 -> Tier 3 | G2205: ='Data (Empaneled)'!F2205 -> No | H2205: ='Data (Empaneled)'!G2205 -> No | I2205: ='Data (Empaneled)'!H2205 -> Yes | ... Z2205: ='Data (Empaneled)'!Y2205 -> 0
A2206: ='Data (Empaneled)'!L2960 -> Haryana|Kurukshetra | B2206: ='Data (Empaneled)'!A2960 -> DR VEENA CHOWDHARY FOUNDATION EYE HOSPITAL | C2206: ='Data (Empaneled)'!B2960 -> Haryana | D2206: ='Data (Empaneled)'!C2960 -> SHAHBADH MARKANDA ,KURUKSHETRA | E2206: ='Data (Empaneled)'!D2960 -> Kurukshetra | F2206: ='Data (Empaneled)'!E2960 -> Tier 3 | G2206: ='Data (Empaneled)'!F2960 -> No | H2206: ='Data (Empaneled)'!G2960 -> No | I2206: ='Data (Empaneled)'!H2960 -> Yes | ... Z2206: ='Data (Empaneled)'!Y2960 -> 0
A2207: ='Data (Empaneled)'!L2206 -> Haryana|Narnaul | B2207: ='Data (Empaneled)'!A2206 -> KRISHNA EYE HOSPITAL | C2207: ='Data (Empaneled)'!B2206 -> Haryana | D2207: ='Data (Empaneled)'!C2206 -> NARNAUL | E2207: ='Data (Empaneled)'!D2206 -> Narnaul | F2207: ='Data (Empaneled)'!E2206 -> Tier 3 | G2207: ='Data (Empaneled)'!F2206 -> No | H2207: ='Data (Empaneled)'!G2206 -> No | I2207: ='Data (Empaneled)'!H2206 -> Yes | ... Z2207: ='Data (Empaneled)'!Y2206 -> 0
A2208: ='Data (Empaneled)'!L2208 -> Madhya Pradesh|Narsinghpur | B2208: ='Data (Empaneled)'!A2208 -> LAXMI NARAYAN MEMORIAL HOSPITAL | C2208: ='Data (Empaneled)'!B2208 -> Madhya Pradesh | D2208: ='Data (Empaneled)'!C2208 -> NARSINGHPUR | E2208: ='Data (Empaneled)'!D2208 -> Narsinghpur | F2208: ='Data (Empaneled)'!E2208 -> Tier 3 | G2208: ='Data (Empaneled)'!F2208 -> Yes | H2208: ='Data (Empaneled)'!G2208 -> No | I2208: ='Data (Empaneled)'!H2208 -> Yes | ... Z2208: ='Data (Empaneled)'!Y2208 -> 0
A2209: ='Data (Empaneled)'!L2209 -> Haryana|Narwana | B2209: ='Data (Empaneled)'!A2209 -> JAYPEE MULTISPECIALITY HOSPITAL | C2209: ='Data (Empaneled)'!B2209 -> Haryana | D2209: ='Data (Empaneled)'!C2209 -> NARWANA | E2209: ='Data (Empaneled)'!D2209 -> Narwana | F2209: ='Data (Empaneled)'!E2209 -> Tier 3 | G2209: ='Data (Empaneled)'!F2209 -> No | H2209: ='Data (Empaneled)'!G2209 -> No | I2209: ='Data (Empaneled)'!H2209 -> No | ... Z2209: ='Data (Empaneled)'!Y2209 -> 0
A2210: ='Data (Empaneled)'!L2210 -> Maharashtra|Nashik | B2210: ='Data (Empaneled)'!A2210 -> Nectar Hospital | C2210: ='Data (Empaneled)'!B2210 -> Maharashtra | D2210: ='Data (Empaneled)'!C2210 -> Nashik | E2210: ='Data (Empaneled)'!D2210 -> Nashik | F2210: ='Data (Empaneled)'!E2210 -> Tier 2B | G2210: ='Data (Empaneled)'!F2210 -> Yes | H2210: ='Data (Empaneled)'!G2210 -> Yes | I2210: ='Data (Empaneled)'!H2210 -> No | ... Z2210: ='Data (Empaneled)'!Y2210 -> 0
A2211: ='Data (Empaneled)'!L2211 -> Maharashtra|Nashik | B2211: ='Data (Empaneled)'!A2211 -> Nulife healthcare hospital | C2211: ='Data (Empaneled)'!B2211 -> Maharashtra | D2211: ='Data (Empaneled)'!C2211 -> NASHIK | E2211: ='Data (Empaneled)'!D2211 -> Nashik | F2211: ='Data (Empaneled)'!E2211 -> Tier 2B | G2211: ='Data (Empaneled)'!F2211 -> Yes | H2211: ='Data (Empaneled)'!G2211 -> Yes | I2211: ='Data (Empaneled)'!H2211 -> Yes | ... Z2211: ='Data (Empaneled)'!Y2211 -> 0
A2212: ='Data (Empaneled)'!L2212 -> Maharashtra|Nashik | B2212: ='Data (Empaneled)'!A2212 -> Saharamedilinehospitalincoalitionwithsaisaharahospital | C2212: ='Data (Empaneled)'!B2212 -> Maharashtra | D2212: ='Data (Empaneled)'!C2212 -> Nashik | E2212: ='Data (Empaneled)'!D2212 -> Nashik | F2212: ='Data (Empaneled)'!E2212 -> Tier 2B | G2212: ='Data (Empaneled)'!F2212 -> No | H2212: ='Data (Empaneled)'!G2212 -> No | I2212: ='Data (Empaneled)'!H2212 -> No | ... Z2212: ='Data (Empaneled)'!Y2212 -> 0
A2213: ='Data (Empaneled)'!L2213 -> Maharashtra|Nashik | B2213: ='Data (Empaneled)'!A2213 -> Sushila multispeciality Hospital | C2213: ='Data (Empaneled)'!B2213 -> Maharashtra | D2213: ='Data (Empaneled)'!C2213 -> nashik | E2213: ='Data (Empaneled)'!D2213 -> Nashik | F2213: ='Data (Empaneled)'!E2213 -> Tier 2B | G2213: ='Data (Empaneled)'!F2213 -> Yes | H2213: ='Data (Empaneled)'!G2213 -> Yes | I2213: ='Data (Empaneled)'!H2213 -> No | ... Z2213: ='Data (Empaneled)'!Y2213 -> 0
A2214: ='Data (Empaneled)'!L2214 -> Maharashtra|Nashik | B2214: ='Data (Empaneled)'!A2214 -> SIDDHI HOSPITAL | C2214: ='Data (Empaneled)'!B2214 -> Maharashtra | D2214: ='Data (Empaneled)'!C2214 -> Nashik | E2214: ='Data (Empaneled)'!D2214 -> Nashik | F2214: ='Data (Empaneled)'!E2214 -> Tier 2B | G2214: ='Data (Empaneled)'!F2214 -> Yes | H2214: ='Data (Empaneled)'!G2214 -> Yes | I2214: ='Data (Empaneled)'!H2214 -> Yes | ... Z2214: ='Data (Empaneled)'!Y2214 -> 0
A2215: ='Data (Empaneled)'!L2215 -> Maharashtra|Nashik | B2215: ='Data (Empaneled)'!A2215 -> Shree Sainath Multispeciality Hospital | C2215: ='Data (Empaneled)'!B2215 -> Maharashtra | D2215: ='Data (Empaneled)'!C2215 -> Nashik | E2215: ='Data (Empaneled)'!D2215 -> Nashik | F2215: ='Data (Empaneled)'!E2215 -> Tier 2B | G2215: ='Data (Empaneled)'!F2215 -> Yes | H2215: ='Data (Empaneled)'!G2215 -> Yes | I2215: ='Data (Empaneled)'!H2215 -> No | ... Z2215: ='Data (Empaneled)'!Y2215 -> 0
A2216: ='Data (Empaneled)'!L2216 -> Maharashtra|Nashik | B2216: ='Data (Empaneled)'!A2216 -> DR BHANGRE'S HOSPITAL | C2216: ='Data (Empaneled)'!B2216 -> Maharashtra | D2216: ='Data (Empaneled)'!C2216 -> NASHIK | E2216: ='Data (Empaneled)'!D2216 -> Nashik | F2216: ='Data (Empaneled)'!E2216 -> Tier 2B | G2216: ='Data (Empaneled)'!F2216 -> No | H2216: ='Data (Empaneled)'!G2216 -> No | I2216: ='Data (Empaneled)'!H2216 -> Yes | ... Z2216: ='Data (Empaneled)'!Y2216 -> 0
A2217: ='Data (Empaneled)'!L2217 -> Maharashtra|Nashik | B2217: ='Data (Empaneled)'!A2217 -> SIDDHARTH HOSPITAL | C2217: ='Data (Empaneled)'!B2217 -> Maharashtra | D2217: ='Data (Empaneled)'!C2217 -> Nashik | E2217: ='Data (Empaneled)'!D2217 -> Nashik | F2217: ='Data (Empaneled)'!E2217 -> Tier 2B | G2217: ='Data (Empaneled)'!F2217 -> No | H2217: ='Data (Empaneled)'!G2217 -> No | I2217: ='Data (Empaneled)'!H2217 -> No | ... Z2217: ='Data (Empaneled)'!Y2217 -> 0
A2218: ='Data (Empaneled)'!L2218 -> Maharashtra|Nashik | B2218: ='Data (Empaneled)'!A2218 -> GROWLIFE WELLNESS SUPERSPECIALITY HOSPITAL | C2218: ='Data (Empaneled)'!B2218 -> Maharashtra | D2218: ='Data (Empaneled)'!C2218 -> NASHIK | E2218: ='Data (Empaneled)'!D2218 -> Nashik | F2218: ='Data (Empaneled)'!E2218 -> Tier 2B | G2218: ='Data (Empaneled)'!F2218 -> Yes | H2218: ='Data (Empaneled)'!G2218 -> Yes | I2218: ='Data (Empaneled)'!H2218 -> Yes | ... Z2218: ='Data (Empaneled)'!Y2218 -> 0
A2219: ='Data (Empaneled)'!L2219 -> Maharashtra|Nashik | B2219: ='Data (Empaneled)'!A2219 -> Dr Patil Maternity Home and Children Hospital | C2219: ='Data (Empaneled)'!B2219 -> Maharashtra | D2219: ='Data (Empaneled)'!C2219 -> Nashik | E2219: ='Data (Empaneled)'!D2219 -> Nashik | F2219: ='Data (Empaneled)'!E2219 -> Tier 2B | G2219: ='Data (Empaneled)'!F2219 -> No | H2219: ='Data (Empaneled)'!G2219 -> No | I2219: ='Data (Empaneled)'!H2219 -> No | ... Z2219: ='Data (Empaneled)'!Y2219 -> 0
... A2408: ='Data (Empaneled)'!L2408 -> Maharashtra|Palse Nashik | B2408: ='Data (Empaneled)'!A2408 -> SHRIKRISHNA CHILDREN AND MULTISPECIALITY HOSPITAL | C2408: ='Data (Empaneled)'!B2408 -> Maharashtra | D2408: ='Data (Empaneled)'!C2408 -> PALSE, NASHIK | E2408: ='Data (Empaneled)'!D2408 -> Palse Nashik | F2408: ='Data (Empaneled)'!E2408 -> Tier 3 | G2408: ='Data (Empaneled)'!F2408 -> No | H2408: ='Data (Empaneled)'!G2408 -> No | I2408: ='Data (Empaneled)'!H2408 -> No | ... Z2408: ='Data (Empaneled)'!Y2408 -> 0
A2409: ='Data (Empaneled)'!L2207 -> Haryana|Narnaul | B2409: ='Data (Empaneled)'!A2207 -> SURYA HOSPITAL | C2409: ='Data (Empaneled)'!B2207 -> Haryana | D2409: ='Data (Empaneled)'!C2207 -> NARNAUL | E2409: ='Data (Empaneled)'!D2207 -> Narnaul | F2409: ='Data (Empaneled)'!E2207 -> Tier 3 | G2409: ='Data (Empaneled)'!F2207 -> No | H2409: ='Data (Empaneled)'!G2207 -> No | I2409: ='Data (Empaneled)'!H2207 -> Yes | ... Z2409: ='Data (Empaneled)'!Y2207 -> 0
A2410: ='Data (Empaneled)'!L2410 -> Chhattisgarh|Pamgarh | B2410: ='Data (Empaneled)'!A2410 -> B R KARSH HOSPITAL | C2410: ='Data (Empaneled)'!B2410 -> Chhattisgarh | D2410: ='Data (Empaneled)'!C2410 -> PAMGARH | E2410: ='Data (Empaneled)'!D2410 -> Pamgarh | F2410: ='Data (Empaneled)'!E2410 -> Tier 3 | G2410: ='Data (Empaneled)'!F2410 -> No | H2410: ='Data (Empaneled)'!G2410 -> No | I2410: ='Data (Empaneled)'!H2410 -> No | ... Z2410: ='Data (Empaneled)'!Y2410 -> 0
A2411: ='Data (Empaneled)'!L2411 -> Haryana|Panchkula | B2411: ='Data (Empaneled)'!A2411 -> Indus Super Specialty Hospital (A Unit of K & Sant Tricity Hospital Pvt. Ltd) | C2411: ='Data (Empaneled)'!B2411 -> Haryana | D2411: ='Data (Empaneled)'!C2411 -> Panchkula | E2411: ='Data (Empaneled)'!D2411 -> Panchkula | F2411: ='Data (Empaneled)'!E2411 -> Tier 3 | G2411: ='Data (Empaneled)'!F2411 -> Yes | H2411: ='Data (Empaneled)'!G2411 -> Yes | I2411: ='Data (Empaneled)'!H2411 -> No | ... Z2411: ='Data (Empaneled)'!Y2411 -> 0
A2412: ='Data (Empaneled)'!L2412 -> West Bengal|Panihati | B2412: ='Data (Empaneled)'!A2412 -> NABANNAA HEALTH INSTITUTE & HOSPITAL | C2412: ='Data (Empaneled)'!B2412 -> West Bengal | D2412: ='Data (Empaneled)'!C2412 -> PANIHATI | E2412: ='Data (Empaneled)'!D2412 -> Panihati | F2412: ='Data (Empaneled)'!E2412 -> Tier 3 | G2412: ='Data (Empaneled)'!F2412 -> No | H2412: ='Data (Empaneled)'!G2412 -> Yes | I2412: ='Data (Empaneled)'!H2412 -> Yes | ... Z2412: ='Data (Empaneled)'!Y2412 -> 0
A2413: ='Data (Empaneled)'!L2413 -> Haryana|Panipat | B2413: ='Data (Empaneled)'!A2413 -> cygnus maharaja aggarsain hospital | C2413: ='Data (Empaneled)'!B2413 -> Haryana | D2413: ='Data (Empaneled)'!C2413 -> PANIPAT | E2413: ='Data (Empaneled)'!D2413 -> Panipat | F2413: ='Data (Empaneled)'!E2413 -> Tier 3 | G2413: ='Data (Empaneled)'!F2413 -> Yes | H2413: ='Data (Empaneled)'!G2413 -> Yes | I2413: ='Data (Empaneled)'!H2413 -> No | ... Z2413: ='Data (Empaneled)'!Y2413 -> 0
A2414: ='Data (Empaneled)'!L2414 -> Haryana|Panipat | B2414: ='Data (Empaneled)'!A2414 -> LOTUS HOSPITAL | C2414: ='Data (Empaneled)'!B2414 -> Haryana | D2414: ='Data (Empaneled)'!C2414 -> PANIPAT | E2414: ='Data (Empaneled)'!D2414 -> Panipat | F2414: ='Data (Empaneled)'!E2414 -> Tier 3 | G2414: ='Data (Empaneled)'!F2414 -> No | H2414: ='Data (Empaneled)'!G2414 -> No | I2414: ='Data (Empaneled)'!H2414 -> No | ... Z2414: ='Data (Empaneled)'!Y2414 -> 0
A2415: ='Data (Empaneled)'!L2415 -> Haryana|Panipat | B2415: ='Data (Empaneled)'!A2415 -> Aarti Nursing Home | C2415: ='Data (Empaneled)'!B2415 -> Haryana | D2415: ='Data (Empaneled)'!C2415 -> PANIPAT | E2415: ='Data (Empaneled)'!D2415 -> Panipat | F2415: ='Data (Empaneled)'!E2415 -> Tier 3 | G2415: ='Data (Empaneled)'!F2415 -> No | H2415: ='Data (Empaneled)'!G2415 -> No | I2415: ='Data (Empaneled)'!H2415 -> No | ... Z2415: ='Data (Empaneled)'!Y2415 -> 0
A2416: ='Data (Empaneled)'!L2409 -> Haryana|Palwal | B2416: ='Data (Empaneled)'!A2409 -> Medicheck Institute of Medical Sciences | C2416: ='Data (Empaneled)'!B2409 -> Haryana | D2416: ='Data (Empaneled)'!C2409 -> Palwal | E2416: ='Data (Empaneled)'!D2409 -> Palwal | F2416: ='Data (Empaneled)'!E2409 -> Tier 3 | G2416: ='Data (Empaneled)'!F2409 -> Yes | H2416: ='Data (Empaneled)'!G2409 -> Yes | I2416: ='Data (Empaneled)'!H2409 -> Yes | ... Z2416: ='Data (Empaneled)'!Y2409 -> 0
A2417: ='Data (Empaneled)'!L2417 -> Haryana|Panipat | B2417: ='Data (Empaneled)'!A2417 -> KALRA HOSPITAL | C2417: ='Data (Empaneled)'!B2417 -> Haryana | D2417: ='Data (Empaneled)'!C2417 -> PANIPAT | E2417: ='Data (Empaneled)'!D2417 -> Panipat | F2417: ='Data (Empaneled)'!E2417 -> Tier 3 | G2417: ='Data (Empaneled)'!F2417 -> No | H2417: ='Data (Empaneled)'!G2417 -> No | I2417: ='Data (Empaneled)'!H2417 -> No | ... Z2417: ='Data (Empaneled)'!Y2417 -> 0
A2418: ='Data (Empaneled)'!L2418 -> Haryana|Panipat | B2418: ='Data (Empaneled)'!A2418 -> Onelife Hospital and Trauma Centre | C2418: ='Data (Empaneled)'!B2418 -> Haryana | D2418: ='Data (Empaneled)'!C2418 -> Panipat | E2418: ='Data (Empaneled)'!D2418 -> Panipat | F2418: ='Data (Empaneled)'!E2418 -> Tier 3 | G2418: ='Data (Empaneled)'!F2418 -> No | H2418: ='Data (Empaneled)'!G2418 -> No | I2418: ='Data (Empaneled)'!H2418 -> No | ... Z2418: ='Data (Empaneled)'!Y2418 -> 0
A2419: ='Data (Empaneled)'!L2419 -> Haryana|Panipat | B2419: ='Data (Empaneled)'!A2419 -> HOPE HOSPITAL | C2419: ='Data (Empaneled)'!B2419 -> Haryana | D2419: ='Data (Empaneled)'!C2419 -> PANIPAT | E2419: ='Data (Empaneled)'!D2419 -> Panipat | F2419: ='Data (Empaneled)'!E2419 -> Tier 3 | G2419: ='Data (Empaneled)'!F2419 -> No | H2419: ='Data (Empaneled)'!G2419 -> No | I2419: ='Data (Empaneled)'!H2419 -> No | ... Z2419: ='Data (Empaneled)'!Y2419 -> 0
...
